Workbook

Sheet Students
A1: Student ID | B1: Khmer Name | C1: English Name | D1: Gender | E1: Current Belt | F1: Months at Current Belt | G1: Eligible for Test? | H1: DOB | I1: Email | J1: Phone | K1: Registration Date | L1: Scholarship | M1: Scholarship Type | N1: Profile Picture ID | O1: E-Sign ID | P1: Height | Q1: Weight
A2: =IFERROR(__xludf.DUMMYFUNCTION("QUERY( IMPORTRANGE(""https://docs.google.com/spreadsheets/d/1oC1mkTIsNSeoiQEOod3PuoHmn0fAHZDJSibfI9Nfu1U/edit?resourcekey=&gid=209778003#gid=209778003"",""Students!A2:K""), ""select * where Col2 <> 'Student ID'"", 1 ) "),"STU-F-001") -> STU-F-001 | B2: =IFERROR(__xludf.DUMMYFUNCTION("""COMPUTED_VALUE"""),"សៅពេជ្រ រិទ្ធីណា") -> សៅពេជ្រ រិទ្ធីណា | C2: =IFERROR(__xludf.DUMMYFUNCTION("""COMPUTED_VALUE"""),"Saopich Rithyna") -> Saopich Rithyna | D2: =IFERROR(__xludf.DUMMYFUNCTION("""COMPUTED_VALUE"""),"Female") -> Female | E2: =IFERROR(__xludf.DUMMYFUNCTION("""COMPUTED_VALUE"""),"Black 1 Poom/Dan") -> Black 1 Poom/Dan | F2: =IFERROR(__xludf.DUMMYFUNCTION("""COMPUTED_VALUE"""),"2") -> 2 | G2: =IFERROR(__xludf.DUMMYFUNCTION("""COMPUTED_VALUE"""),"NO") -> NO | H2: =IFERROR(__xludf.DUMMYFUNCTION("""COMPUTED_VALUE"""),"21-Feb-2008") -> 21-Feb-2008 | I2: =IFERROR(__xludf.DUMMYFUNCTION("""COMPUTED_VALUE"""),"pichrithynaa@gmail.com") -> pichrithynaa@gmail.com | J2: =IFERROR(__xludf.DUMMYFUNCTION("""COMPUTED_VALUE"""),"081 570 816") -> 081 570 816 | K2: =IFERROR(__xludf.DUMMYFUNCTION("""COMPUTED_VALUE"""),"18-Aug-2025") -> 18-Aug-2025 | L2: Yes | M2: Full | N2: 1lBmAnT-53eMCmhIc0tjwv9Hb1V9gfvsG
A3: =IFERROR(__xludf.DUMMYFUNCTION("""COMPUTED_VALUE"""),"STU-M-002") -> STU-M-002 | B3: =IFERROR(__xludf.DUMMYFUNCTION("""COMPUTED_VALUE"""),"ហាក់ លីម៉េង") -> ហាក់ លីម៉េង | C3: =IFERROR(__xludf.DUMMYFUNCTION("""COMPUTED_VALUE"""),"Hak Lymeng") -> Hak Lymeng | D3: =IFERROR(__xludf.DUMMYFUNCTION("""COMPUTED_VALUE"""),"Male") -> Male | E3: =IFERROR(__xludf.DUMMYFUNCTION("""COMPUTED_VALUE"""),"Yellow") -> Yellow | F3: =IFERROR(__xludf.DUMMYFUNCTION("""COMPUTED_VALUE"""),4.0) -> 4 | G3: =IFERROR(__xludf.DUMMYFUNCTION("""COMPUTED_VALUE"""),"YES") -> YES | H3: =IFERROR(__xludf.DUMMYFUNCTION("""COMPUTED_VALUE"""),40014.0) -> 40014 | I3: =IFERROR(__xludf.DUMMYFUNCTION("""COMPUTED_VALUE"""),"lymeng7051@gmail.com") -> lymeng7051@gmail.com | J3: =IFERROR(__xludf.DUMMYFUNCTION("""COMPUTED_VALUE"""),"095328185") -> 095328185 | K3: =IFERROR(__xludf.DUMMYFUNCTION("""COMPUTED_VALUE"""),45887.0) -> 45887 | L3: Yes | M3: Athlete | N3: 14T-8UcnZ4gca2TN_LD8KfNLrp5A8aoSB
A4: =IFERROR(__xludf.DUMMYFUNCTION("""COMPUTED_VALUE"""),"STU-F-003") -> STU-F-003 | B4: =IFERROR(__xludf.DUMMYFUNCTION("""COMPUTED_VALUE"""),"អុឹង ចំរើនរាសី") -> អុឹង ចំរើនរាសី | C4: =IFERROR(__xludf.DUMMYFUNCTION("""COMPUTED_VALUE"""),"Oeng Chamroeunreasey") -> Oeng Chamroeunreasey | D4: =IFERROR(__xludf.DUMMYFUNCTION("""COMPUTED_VALUE"""),"Female") -> Female | E4: =IFERROR(__xludf.DUMMYFUNCTION("""COMPUTED_VALUE"""),"Black 1 Poom/Dan") -> Black 1 Poom/Dan | F4: =IFERROR(__xludf.DUMMYFUNCTION("""COMPUTED_VALUE"""),21.0) -> 21 | G4: =IFERROR(__xludf.DUMMYFUNCTION("""COMPUTED_VALUE"""),"YES") -> YES | H4: =IFERROR(__xludf.DUMMYFUNCTION("""COMPUTED_VALUE"""),40178.0) -> 40178 | I4: =IFERROR(__xludf.DUMMYFUNCTION("""COMPUTED_VALUE"""),"chamroeunreaseyoeng777@gmail.com") -> chamroeunreaseyoeng777@gmail.com | J4: =IFERROR(__xludf.DUMMYFUNCTION("""COMPUTED_VALUE"""),"017319161") -> 017319161 | K4: =IFERROR(__xludf.DUMMYFUNCTION("""COMPUTED_VALUE"""),45887.0) -> 45887 | L4: No | N4: 13K01dr_3gn7GVXyA0RBF5dieavfPfvxw
A5: =IFERROR(__xludf.DUMMYFUNCTION("""COMPUTED_VALUE"""),"STU-F-004") -> STU-F-004 | B5: =IFERROR(__xludf.DUMMYFUNCTION("""COMPUTED_VALUE"""),"មិត សុធា") -> មិត សុធា | C5: =IFERROR(__xludf.DUMMYFUNCTION("""COMPUTED_VALUE"""),"Sothea Mith") -> Sothea Mith | D5: =IFERROR(__xludf.DUMMYFUNCTION("""COMPUTED_VALUE"""),"Female") -> Female | E5: =IFERROR(__xludf.DUMMYFUNCTION("""COMPUTED_VALUE"""),"Yellow") -> Yellow | F5: =IFERROR(__xludf.DUMMYFUNCTION("""COMPUTED_VALUE"""),4.0) -> 4 | G5: =IFERROR(__xludf.DUMMYFUNCTION("""COMPUTED_VALUE"""),"YES") -> YES | H5: =IFERROR(__xludf.DUMMYFUNCTION("""COMPUTED_VALUE"""),39856.0) -> 39856 | I5: =IFERROR(__xludf.DUMMYFUNCTION("""COMPUTED_VALUE"""),"sothea4564@gmail.com") -> sothea4564@gmail.com | J5: =IFERROR(__xludf.DUMMYFUNCTION("""COMPUTED_VALUE"""),"0764977501") -> 0764977501 | K5: =IFERROR(__xludf.DUMMYFUNCTION("""COMPUTED_VALUE"""),45914.0) -> 45914 | L5: No | N5: 1xdzQPdHMhjodilRSOfZOVhAcnzs4e7CG
A6: =IFERROR(__xludf.DUMMYFUNCTION("""COMPUTED_VALUE"""),"STU-F-005") -> STU-F-005 | B6: =IFERROR(__xludf.DUMMYFUNCTION("""COMPUTED_VALUE"""),"ហែម កែវទិត្យសុបុណ្យនារី") -> ហែម កែវទិត្យសុបុណ្យនារី | C6: =IFERROR(__xludf.DUMMYFUNCTION("""COMPUTED_VALUE"""),"Hem Keotetsobonneary") -> Hem Keotetsobonneary | D6: =IFERROR(__xludf.DUMMYFUNCTION("""COMPUTED_VALUE"""),"Female") -> Female | E6: =IFERROR(__xludf.DUMMYFUNCTION("""COMPUTED_VALUE"""),"Red") -> Red | F6: =IFERROR(__xludf.DUMMYFUNCTION("""COMPUTED_VALUE"""),13.0) -> 13 | G6: =IFERROR(__xludf.DUMMYFUNCTION("""COMPUTED_VALUE"""),"YES") -> YES | H6: =IFERROR(__xludf.DUMMYFUNCTION("""COMPUTED_VALUE"""),39460.0) -> 39460 | I6: =IFERROR(__xludf.DUMMYFUNCTION("""COMPUTED_VALUE"""),"sobonneary.hem@gmail.com") -> sobonneary.hem@gmail.com | J6: =IFERROR(__xludf.DUMMYFUNCTION("""COMPUTED_VALUE"""),"017334430") -> 017334430 | K6: =IFERROR(__xludf.DUMMYFUNCTION("""COMPUTED_VALUE"""),45916.0) -> 45916 | L6: No
A7: =IFERROR(__xludf.DUMMYFUNCTION("""COMPUTED_VALUE"""),"STU-F-006") -> STU-F-006 | B7: =IFERROR(__xludf.DUMMYFUNCTION("""COMPUTED_VALUE"""),"នៅ ធីតាពីន") -> នៅ ធីតាពីន | C7: =IFERROR(__xludf.DUMMYFUNCTION("""COMPUTED_VALUE"""),"Neou Thidapin") -> Neou Thidapin | D7: =IFERROR(__xludf.DUMMYFUNCTION("""COMPUTED_VALUE"""),"Female") -> Female | E7: =IFERROR(__xludf.DUMMYFUNCTION("""COMPUTED_VALUE"""),"Black 2 Poom/Dan") -> Black 2 Poom/Dan | F7: =IFERROR(__xludf.DUMMYFUNCTION("""COMPUTED_VALUE"""),14.0) -> 14 | G7: =IFERROR(__xludf.DUMMYFUNCTION("""COMPUTED_VALUE"""),"NO") -> NO | H7: =IFERROR(__xludf.DUMMYFUNCTION("""COMPUTED_VALUE"""),38645.0) -> 38645 | I7: =IFERROR(__xludf.DUMMYFUNCTION("""COMPUTED_VALUE"""),"thidapinneou@gmail.com") -> thidapinneou@gmail.com | J7: =IFERROR(__xludf.DUMMYFUNCTION("""COMPUTED_VALUE"""),"0766609276") -> 0766609276 | K7: =IFERROR(__xludf.DUMMYFUNCTION("""COMPUTED_VALUE"""),45925.0) -> 45925 | L7: Yes | M7: 0.2 | N7: 1cDx6ImJ1Sjb8V4QSeTpWjilAA-3Jhudj
A8: =IFERROR(__xludf.DUMMYFUNCTION("""COMPUTED_VALUE"""),"STU-F-007") -> STU-F-007 | B8: =IFERROR(__xludf.DUMMYFUNCTION("""COMPUTED_VALUE"""),"អាពូបាកា រ៉ូសនាវ៉ាត្តី ") -> អាពូបាកា រ៉ូសនាវ៉ាត្តី | C8: =IFERROR(__xludf.DUMMYFUNCTION("""COMPUTED_VALUE"""),"Aboubakar Rosnavattey ") -> Aboubakar Rosnavattey | D8: =IFERROR(__xludf.DUMMYFUNCTION("""COMPUTED_VALUE"""),"Female") -> Female | E8: =IFERROR(__xludf.DUMMYFUNCTION("""COMPUTED_VALUE"""),"Black 1 Poom/Dan") -> Black 1 Poom/Dan | F8: =IFERROR(__xludf.DUMMYFUNCTION("""COMPUTED_VALUE"""),24.0) -> 24 | G8: =IFERROR(__xludf.DUMMYFUNCTION("""COMPUTED_VALUE"""),"YES") -> YES | H8: =IFERROR(__xludf.DUMMYFUNCTION("""COMPUTED_VALUE"""),39981.0) -> 39981 | I8: =IFERROR(__xludf.DUMMYFUNCTION("""COMPUTED_VALUE"""),"rosnavatey2009@gmail.com") -> rosnavatey2009@gmail.com | J8: =IFERROR(__xludf.DUMMYFUNCTION("""COMPUTED_VALUE"""),"0963586064") -> 0963586064 | K8: =IFERROR(__xludf.DUMMYFUNCTION("""COMPUTED_VALUE"""),45928.0) -> 45928 | L8: Yes | M8: Women in Sport | N8: 1rTvNSRWn013sngIp3KfND0HU7ickAzIP
A9: =IFERROR(__xludf.DUMMYFUNCTION("""COMPUTED_VALUE"""),"STU-F-008") -> STU-F-008 | B9: =IFERROR(__xludf.DUMMYFUNCTION("""COMPUTED_VALUE"""),"នុត ដានីតា") -> នុត ដានីតា | C9: =IFERROR(__xludf.DUMMYFUNCTION("""COMPUTED_VALUE"""),"Nuth Danita") -> Nuth Danita | D9: =IFERROR(__xludf.DUMMYFUNCTION("""COMPUTED_VALUE"""),"Female") -> Female | E9: =IFERROR(__xludf.DUMMYFUNCTION("""COMPUTED_VALUE"""),"Black 1 Poom/Dan") -> Black 1 Poom/Dan | F9: =IFERROR(__xludf.DUMMYFUNCTION("""COMPUTED_VALUE"""),5.0) -> 5 | G9: =IFERROR(__xludf.DUMMYFUNCTION("""COMPUTED_VALUE"""),"NO") -> NO | H9: =IFERROR(__xludf.DUMMYFUNCTION("""COMPUTED_VALUE"""),38107.0) -> 38107 | I9: =IFERROR(__xludf.DUMMYFUNCTION("""COMPUTED_VALUE"""),"nuthdanita@gmail.com") -> nuthdanita@gmail.com | J9: =IFERROR(__xludf.DUMMYFUNCTION("""COMPUTED_VALUE"""),"0967942875") -> 0967942875 | K9: =IFERROR(__xludf.DUMMYFUNCTION("""COMPUTED_VALUE"""),45934.0) -> 45934 | L9: Yes | M9: Athlete | N9: 14x7sj-_tMTcQJ6ciIDCBw_Orz48wpTCu
A10: =IFERROR(__xludf.DUMMYFUNCTION("""COMPUTED_VALUE"""),"STU-M-009") -> STU-M-009 | B10: =IFERROR(__xludf.DUMMYFUNCTION("""COMPUTED_VALUE"""),"ភេន ឌីណា") -> ភេន ឌីណា | C10: =IFERROR(__xludf.DUMMYFUNCTION("""COMPUTED_VALUE"""),"Dina Pan ") -> Dina Pan | D10: =IFERROR(__xludf.DUMMYFUNCTION("""COMPUTED_VALUE"""),"Male") -> Male | E10: =IFERROR(__xludf.DUMMYFUNCTION("""COMPUTED_VALUE"""),"Blue") -> Blue | H10: =IFERROR(__xludf.DUMMYFUNCTION("""COMPUTED_VALUE"""),38730.0) -> 38730 | I10: =IFERROR(__xludf.DUMMYFUNCTION("""COMPUTED_VALUE"""),"gamingdina0@gmail.com") -> gamingdina0@gmail.com | J10: =IFERROR(__xludf.DUMMYFUNCTION("""COMPUTED_VALUE"""),"0976402066") -> 0976402066 | K10: =IFERROR(__xludf.DUMMYFUNCTION("""COMPUTED_VALUE"""),45944.0) -> 45944 | L10: Yes
A11: =IFERROR(__xludf.DUMMYFUNCTION("""COMPUTED_VALUE"""),"STU-M-010") -> STU-M-010 | B11: =IFERROR(__xludf.DUMMYFUNCTION("""COMPUTED_VALUE"""),"សោម សុវិន") -> សោម សុវិន | C11: =IFERROR(__xludf.DUMMYFUNCTION("""COMPUTED_VALUE"""),"Soam Sovin") -> Soam Sovin | D11: =IFERROR(__xludf.DUMMYFUNCTION("""COMPUTED_VALUE"""),"Male") -> Male | E11: =IFERROR(__xludf.DUMMYFUNCTION("""COMPUTED_VALUE"""),"Brown") -> Brown | H11: =IFERROR(__xludf.DUMMYFUNCTION("""COMPUTED_VALUE"""),38311.0) -> 38311 | I11: =IFERROR(__xludf.DUMMYFUNCTION("""COMPUTED_VALUE"""),"rukito5459@gmail.com") -> rukito5459@gmail.com | J11: =IFERROR(__xludf.DUMMYFUNCTION("""COMPUTED_VALUE"""),"077549456") -> 077549456 | K11: =IFERROR(__xludf.DUMMYFUNCTION("""COMPUTED_VALUE"""),45948.0) -> 45948
A12: =IFERROR(__xludf.DUMMYFUNCTION("""COMPUTED_VALUE"""),"STU-F-011") -> STU-F-011 | B12: =IFERROR(__xludf.DUMMYFUNCTION("""COMPUTED_VALUE"""),"ឃានកែវ បាបឺរ៉ា") -> ឃានកែវ បាបឺរ៉ា | C12: =IFERROR(__xludf.DUMMYFUNCTION("""COMPUTED_VALUE"""),"Kheankeo Babera") -> Kheankeo Babera | D12: =IFERROR(__xludf.DUMMYFUNCTION("""COMPUTED_VALUE"""),"Female") -> Female | E12: =IFERROR(__xludf.DUMMYFUNCTION("""COMPUTED_VALUE"""),"Black 1 Poom/Dan") -> Black 1 Poom/Dan | F12: =IFERROR(__xludf.DUMMYFUNCTION("""COMPUTED_VALUE"""),14.0) -> 14 | G12: =IFERROR(__xludf.DUMMYFUNCTION("""COMPUTED_VALUE"""),"YES") -> YES | H12: =IFERROR(__xludf.DUMMYFUNCTION("""COMPUTED_VALUE"""),38758.0) -> 38758 | I12: =IFERROR(__xludf.DUMMYFUNCTION("""COMPUTED_VALUE"""),"kkeobbabera@gmail.com") -> kkeobbabera@gmail.com | J12: =IFERROR(__xludf.DUMMYFUNCTION("""COMPUTED_VALUE"""),"093236598") -> 093236598 | K12: =IFERROR(__xludf.DUMMYFUNCTION("""COMPUTED_VALUE"""),45962.0) -> 45962
A13: =IFERROR(__xludf.DUMMYFUNCTION("""COMPUTED_VALUE"""),"STU-F-012") -> STU-F-012 | B13: =IFERROR(__xludf.DUMMYFUNCTION("""COMPUTED_VALUE"""),"ទី វរលក្ខណ៍") -> ទី វរលក្ខណ៍ | C13: =IFERROR(__xludf.DUMMYFUNCTION("""COMPUTED_VALUE"""),"Ty Vorleak") -> Ty Vorleak | D13: =IFERROR(__xludf.DUMMYFUNCTION("""COMPUTED_VALUE"""),"Female") -> Female | E13: =IFERROR(__xludf.DUMMYFUNCTION("""COMPUTED_VALUE"""),"Black 1 Poom/Dan") -> Black 1 Poom/Dan | F13: =IFERROR(__xludf.DUMMYFUNCTION("""COMPUTED_VALUE"""),8.0) -> 8 | G13: =IFERROR(__xludf.DUMMYFUNCTION("""COMPUTED_VALUE"""),"NO") -> NO | H13: =IFERROR(__xludf.DUMMYFUNCTION("""COMPUTED_VALUE"""),39916.0) -> 39916 | I13: =IFERROR(__xludf.DUMMYFUNCTION("""COMPUTED_VALUE"""),"nitaeng168@gmail.com") -> nitaeng168@gmail.com | J13: =IFERROR(__xludf.DUMMYFUNCTION("""COMPUTED_VALUE"""),"011 892 656") -> 011 892 656 | K13: =IFERROR(__xludf.DUMMYFUNCTION("""COMPUTED_VALUE"""),45964.0) -> 45964 | L13: No
A14: =IFERROR(__xludf.DUMMYFUNCTION("""COMPUTED_VALUE"""),"STU-F-013") -> STU-F-013 | B14: =IFERROR(__xludf.DUMMYFUNCTION("""COMPUTED_VALUE"""),"សំនៀង ឡេអុងទីន") -> សំនៀង ឡេអុងទីន | C14: =IFERROR(__xludf.DUMMYFUNCTION("""COMPUTED_VALUE"""),"Samneang Leongtin") -> Samneang Leongtin | D14: =IFERROR(__xludf.DUMMYFUNCTION("""COMPUTED_VALUE"""),"Female") -> Female | E14: =IFERROR(__xludf.DUMMYFUNCTION("""COMPUTED_VALUE"""),"White") -> White | F14: =IFERROR(__xludf.DUMMYFUNCTION("""COMPUTED_VALUE"""),2.0) -> 2 | G14: =IFERROR(__xludf.DUMMYFUNCTION("""COMPUTED_VALUE"""),"NO") -> NO | H14: =IFERROR(__xludf.DUMMYFUNCTION("""COMPUTED_VALUE"""),39143.0) -> 39143 | I14: =IFERROR(__xludf.DUMMYFUNCTION("""COMPUTED_VALUE"""),"leongtin92@gmail.com") -> leongtin92@gmail.com | J14: =IFERROR(__xludf.DUMMYFUNCTION("""COMPUTED_VALUE"""),"085662045") -> 085662045 | K14: =IFERROR(__xludf.DUMMYFUNCTION("""COMPUTED_VALUE"""),45964.0) -> 45964 | L14: No
A15: =IFERROR(__xludf.DUMMYFUNCTION("""COMPUTED_VALUE"""),"STU-F-014") -> STU-F-014 | B15: =IFERROR(__xludf.DUMMYFUNCTION("""COMPUTED_VALUE"""),"ធួក សុធានីន") -> ធួក សុធានីន | C15: =IFERROR(__xludf.DUMMYFUNCTION("""COMPUTED_VALUE"""),"Thuok Sotheanin ") -> Thuok Sotheanin | D15: =IFERROR(__xludf.DUMMYFUNCTION("""COMPUTED_VALUE"""),"Female") -> Female | E15: =IFERROR(__xludf.DUMMYFUNCTION("""COMPUTED_VALUE"""),"White") -> White | F15: =IFERROR(__xludf.DUMMYFUNCTION("""COMPUTED_VALUE"""),2.0) -> 2 | G15: =IFERROR(__xludf.DUMMYFUNCTION("""COMPUTED_VALUE"""),"NO") -> NO | H15: =IFERROR(__xludf.DUMMYFUNCTION("""COMPUTED_VALUE"""),40028.0) -> 40028 | I15: =IFERROR(__xludf.DUMMYFUNCTION("""COMPUTED_VALUE"""),"moshii12123@gmail.com") -> moshii12123@gmail.com | J15: =IFERROR(__xludf.DUMMYFUNCTION("""COMPUTED_VALUE"""),"0966191202") -> 0966191202 | K15: =IFERROR(__xludf.DUMMYFUNCTION("""COMPUTED_VALUE"""),45964.0) -> 45964 | L15: No
A16: =IFERROR(__xludf.DUMMYFUNCTION("""COMPUTED_VALUE"""),"STU-F-015") -> STU-F-015 | B16: =IFERROR(__xludf.DUMMYFUNCTION("""COMPUTED_VALUE"""),"វ៉ាន់ដូរ ជេនិសា") -> វ៉ាន់ដូរ ជេនិសា | C16: =IFERROR(__xludf.DUMMYFUNCTION("""COMPUTED_VALUE"""),"Vando Chenisa") -> Vando Chenisa | D16: =IFERROR(__xludf.DUMMYFUNCTION("""COMPUTED_VALUE"""),"Female") -> Female | E16: =IFERROR(__xludf.DUMMYFUNCTION("""COMPUTED_VALUE"""),"Green") -> Green | F16: =IFERROR(__xludf.DUMMYFUNCTION("""COMPUTED_VALUE"""),1.0) -> 1 | G16: =IFERROR(__xludf.DUMMYFUNCTION("""COMPUTED_VALUE"""),"NO") -> NO | H16: =IFERROR(__xludf.DUMMYFUNCTION("""COMPUTED_VALUE"""),41307.0) -> 41307 | I16: =IFERROR(__xludf.DUMMYFUNCTION("""COMPUTED_VALUE"""),"chenisavando@gmail.com") -> chenisavando@gmail.com | J16: =IFERROR(__xludf.DUMMYFUNCTION("""COMPUTED_VALUE"""),"098808972") -> 098808972 | K16: =IFERROR(__xludf.DUMMYFUNCTION("""COMPUTED_VALUE"""),45971.0) -> 45971 | L16: No | N16: 1njLK28xhTtCF03sC1pF1fnrGndlKskUi
A17: =IFERROR(__xludf.DUMMYFUNCTION("""COMPUTED_VALUE"""),"STU-F-016") -> STU-F-016 | B17: =IFERROR(__xludf.DUMMYFUNCTION("""COMPUTED_VALUE"""),"វ៉ាន់ដូរ ជេនិតា") -> វ៉ាន់ដូរ ជេនិតា | C17: =IFERROR(__xludf.DUMMYFUNCTION("""COMPUTED_VALUE"""),"Vando Chenita") -> Vando Chenita | D17: =IFERROR(__xludf.DUMMYFUNCTION("""COMPUTED_VALUE"""),"Female") -> Female | E17: =IFERROR(__xludf.DUMMYFUNCTION("""COMPUTED_VALUE"""),"Brown") -> Brown | F17: =IFERROR(__xludf.DUMMYFUNCTION("""COMPUTED_VALUE"""),1.0) -> 1 | G17: =IFERROR(__xludf.DUMMYFUNCTION("""COMPUTED_VALUE"""),"NO") -> NO | H17: =IFERROR(__xludf.DUMMYFUNCTION("""COMPUTED_VALUE"""),40225.0) -> 40225 | I17: =IFERROR(__xludf.DUMMYFUNCTION("""COMPUTED_VALUE"""),"b3cg1eee@gmail.com") -> b3cg1eee@gmail.com | J17: =IFERROR(__xludf.DUMMYFUNCTION("""COMPUTED_VALUE"""),"099 224 257") -> 099 224 257 | K17: =IFERROR(__xludf.DUMMYFUNCTION("""COMPUTED_VALUE"""),45971.0) -> 45971 | L17: No | N17: 1yC4QSq0xM6xMqq1SvJVv8lcKsXzlx37n
A18: =IFERROR(__xludf.DUMMYFUNCTION("""COMPUTED_VALUE"""),"STU-F-017") -> STU-F-017 | B18: =IFERROR(__xludf.DUMMYFUNCTION("""COMPUTED_VALUE"""),"ប៉ែន សុធា") -> ប៉ែន សុធា | C18: =IFERROR(__xludf.DUMMYFUNCTION("""COMPUTED_VALUE"""),"Pen Sothea") -> Pen Sothea | D18: =IFERROR(__xludf.DUMMYFUNCTION("""COMPUTED_VALUE"""),"Female") -> Female | E18: =IFERROR(__xludf.DUMMYFUNCTION("""COMPUTED_VALUE"""),"Red") -> Red | F18: =IFERROR(__xludf.DUMMYFUNCTION("""COMPUTED_VALUE"""),1.0) -> 1 | G18: =IFERROR(__xludf.DUMMYFUNCTION("""COMPUTED_VALUE"""),"NO") -> NO | H18: =IFERROR(__xludf.DUMMYFUNCTION("""COMPUTED_VALUE"""),39610.0) -> 39610 | I18: =IFERROR(__xludf.DUMMYFUNCTION("""COMPUTED_VALUE"""),"pensothea937@gmail.com") -> pensothea937@gmail.com | J18: =IFERROR(__xludf.DUMMYFUNCTION("""COMPUTED_VALUE"""),"011-211-237") -> 011-211-237 | K18: =IFERROR(__xludf.DUMMYFUNCTION("""COMPUTED_VALUE"""),45971.0) -> 45971 | L18: No | N18: 1Lh_jIP7FgZmJXiJRmv3NSO-G4RhWQIzK
A19: =IFERROR(__xludf.DUMMYFUNCTION("""COMPUTED_VALUE"""),"STU-F-018") -> STU-F-018 | B19: =IFERROR(__xludf.DUMMYFUNCTION("""COMPUTED_VALUE"""),"នន់ សីហា") -> នន់ សីហា | C19: =IFERROR(__xludf.DUMMYFUNCTION("""COMPUTED_VALUE"""),"Nun Seyha") -> Nun Seyha | D19: =IFERROR(__xludf.DUMMYFUNCTION("""COMPUTED_VALUE"""),"Female") -> Female | E19: =IFERROR(__xludf.DUMMYFUNCTION("""COMPUTED_VALUE"""),"White") -> White | F19: =IFERROR(__xludf.DUMMYFUNCTION("""COMPUTED_VALUE"""),1.0) -> 1 | G19: =IFERROR(__xludf.DUMMYFUNCTION("""COMPUTED_VALUE"""),"NO") -> NO | H19: =IFERROR(__xludf.DUMMYFUNCTION("""COMPUTED_VALUE"""),37478.0) -> 37478 | I19: =IFERROR(__xludf.DUMMYFUNCTION("""COMPUTED_VALUE"""),"nunseyha5@gmail.com") -> nunseyha5@gmail.com | J19: =IFERROR(__xludf.DUMMYFUNCTION("""COMPUTED_VALUE"""),"015421982") -> 015421982 | K19: =IFERROR(__xludf.DUMMYFUNCTION("""COMPUTED_VALUE"""),45972.0) -> 45972 | L19: No
A20: =IFERROR(__xludf.DUMMYFUNCTION("""COMPUTED_VALUE"""),"STU-F-019") -> STU-F-019 | B20: =IFERROR(__xludf.DUMMYFUNCTION("""COMPUTED_VALUE"""),"ចៅ បូរ៉ែនណា") -> ចៅ បូរ៉ែនណា | C20: =IFERROR(__xludf.DUMMYFUNCTION("""COMPUTED_VALUE"""),"Chau Boreinna ") -> Chau Boreinna | D20: =IFERROR(__xludf.DUMMYFUNCTION("""COMPUTED_VALUE"""),"Female") -> Female | E20: =IFERROR(__xludf.DUMMYFUNCTION("""COMPUTED_VALUE"""),"Blue") -> Blue | F20: =IFERROR(__xludf.DUMMYFUNCTION("""COMPUTED_VALUE"""),1.0) -> 1 | G20: =IFERROR(__xludf.DUMMYFUNCTION("""COMPUTED_VALUE"""),"NO") -> NO | H20: =IFERROR(__xludf.DUMMYFUNCTION("""COMPUTED_VALUE"""),38851.0) -> 38851 | I20: =IFERROR(__xludf.DUMMYFUNCTION("""COMPUTED_VALUE"""),"boreinnachau@gmail.com") -> boreinnachau@gmail.com | J20: =IFERROR(__xludf.DUMMYFUNCTION("""COMPUTED_VALUE"""),"017804477") -> 017804477 | K20: =IFERROR(__xludf.DUMMYFUNCTION("""COMPUTED_VALUE"""),45973.0) -> 45973 | L20: No | N20: 1DOjd_1tOta-mJwKJQuhzt70rpYWEclP9 | O20: 1jyIG3mBkNSEm5GiU2ZznFX-yZBd2k8xm | P20: 160 | Q20: 53
A21: =IFERROR(__xludf.DUMMYFUNCTION("""COMPUTED_VALUE"""),"STU-M-020") -> STU-M-020 | B21: =IFERROR(__xludf.DUMMYFUNCTION("""COMPUTED_VALUE"""),"សុភា រតនៈ") -> សុភា រតនៈ | C21: =IFERROR(__xludf.DUMMYFUNCTION("""COMPUTED_VALUE"""),"Sophea Ratanak") -> Sophea Ratanak | D21: =IFERROR(__xludf.DUMMYFUNCTION("""COMPUTED_VALUE"""),"Male") -> Male | E21: =IFERROR(__xludf.DUMMYFUNCTION("""COMPUTED_VALUE"""),"Blue") -> Blue | F21: =IFERROR(__xludf.DUMMYFUNCTION("""COMPUTED_VALUE"""),1.0) -> 1 | G21: =IFERROR(__xludf.DUMMYFUNCTION("""COMPUTED_VALUE"""),"NO") -> NO | H21: =IFERROR(__xludf.DUMMYFUNCTION("""COMPUTED_VALUE"""),39389.0) -> 39389 | I21: =IFERROR(__xludf.DUMMYFUNCTION("""COMPUTED_VALUE"""),"sophearatanakk@gmail.com") -> sophearatanakk@gmail.com | J21: =IFERROR(__xludf.DUMMYFUNCTION("""COMPUTED_VALUE"""),"016759209 (on telegram)") -> 016759209 (on telegram) | K21: =IFERROR(__xludf.DUMMYFUNCTION("""COMPUTED_VALUE"""),45973.0) -> 45973 | L21: No | N21: 1U0oP0YyNrlccibP5z7YNvl9pJfwebY92 | O21: 1VXdQglqLcyFsRjcGiaT3s5295s20Fx3g | P21: 177 | Q21: 65
A22: =IFERROR(__xludf.DUMMYFUNCTION("""COMPUTED_VALUE"""),"STU-M-021") -> STU-M-021 | B22: =IFERROR(__xludf.DUMMYFUNCTION("""COMPUTED_VALUE"""),"យ៉ែម សភា") -> យ៉ែម សភា | C22: =IFERROR(__xludf.DUMMYFUNCTION("""COMPUTED_VALUE"""),"Yem Sakphea") -> Yem Sakphea | D22: =IFERROR(__xludf.DUMMYFUNCTION("""COMPUTED_VALUE"""),"Male") -> Male | E22: =IFERROR(__xludf.DUMMYFUNCTION("""COMPUTED_VALUE"""),"White") -> White | F22: =IFERROR(__xludf.DUMMYFUNCTION("""COMPUTED_VALUE"""),1.0) -> 1 | G22: =IFERROR(__xludf.DUMMYFUNCTION("""COMPUTED_VALUE"""),"NO") -> NO | H22: =IFERROR(__xludf.DUMMYFUNCTION("""COMPUTED_VALUE"""),38273.0) -> 38273 | I22: =IFERROR(__xludf.DUMMYFUNCTION("""COMPUTED_VALUE"""),"sakphea2000168@gmail.com") -> sakphea2000168@gmail.com | J22: =IFERROR(__xludf.DUMMYFUNCTION("""COMPUTED_VALUE"""),"016718783") -> 016718783 | K22: =IFERROR(__xludf.DUMMYFUNCTION("""COMPUTED_VALUE"""),45974.0) -> 45974 | L22: No
A23: =IFERROR(__xludf.DUMMYFUNCTION("""COMPUTED_VALUE"""),"STU-M-022") -> STU-M-022 | B23: =IFERROR(__xludf.DUMMYFUNCTION("""COMPUTED_VALUE"""),"ឈៀង ហុងហេង") -> ឈៀង ហុងហេង | C23: =IFERROR(__xludf.DUMMYFUNCTION("""COMPUTED_VALUE"""),"Chheang Hongheng ") -> Chheang Hongheng | D23: =IFERROR(__xludf.DUMMYFUNCTION("""COMPUTED_VALUE"""),"Male") -> Male | E23: =IFERROR(__xludf.DUMMYFUNCTION("""COMPUTED_VALUE"""),"Black 1 Poom/Dan") -> Black 1 Poom/Dan | F23: =IFERROR(__xludf.DUMMYFUNCTION("""COMPUTED_VALUE"""),11.0) -> 11 | G23: =IFERROR(__xludf.DUMMYFUNCTION("""COMPUTED_VALUE"""),"NO") -> NO | H23: =IFERROR(__xludf.DUMMYFUNCTION("""COMPUTED_VALUE"""),37574.0) -> 37574 | I23: =IFERROR(__xludf.DUMMYFUNCTION("""COMPUTED_VALUE"""),"chheanghongheng6@gmail.com") -> chheanghongheng6@gmail.com | J23: =IFERROR(__xludf.DUMMYFUNCTION("""COMPUTED_VALUE"""),"070847172") -> 070847172 | K23: =IFERROR(__xludf.DUMMYFUNCTION("""COMPUTED_VALUE"""),45975.0) -> 45975 | L23: No
A24: =IFERROR(__xludf.DUMMYFUNCTION("""COMPUTED_VALUE"""),"STU-F-023") -> STU-F-023 | B24: =IFERROR(__xludf.DUMMYFUNCTION("""COMPUTED_VALUE"""),"ផាន់ អារ៉ាន់យ៉ា") -> ផាន់ អារ៉ាន់យ៉ា | C24: =IFERROR(__xludf.DUMMYFUNCTION("""COMPUTED_VALUE"""),"Phan Aranya") -> Phan Aranya | D24: =IFERROR(__xludf.DUMMYFUNCTION("""COMPUTED_VALUE"""),"Female") -> Female | E24: =IFERROR(__xludf.DUMMYFUNCTION("""COMPUTED_VALUE"""),"White") -> White | F24: =IFERROR(__xludf.DUMMYFUNCTION("""COMPUTED_VALUE"""),1.0) -> 1 | G24: =IFERROR(__xludf.DUMMYFUNCTION("""COMPUTED_VALUE"""),"NO") -> NO | H24: =IFERROR(__xludf.DUMMYFUNCTION("""COMPUTED_VALUE"""),38337.0) -> 38337 | I24: =IFERROR(__xludf.DUMMYFUNCTION("""COMPUTED_VALUE"""),"pookieluvpeachie@gmail.com") -> pookieluvpeachie@gmail.com | J24: =IFERROR(__xludf.DUMMYFUNCTION("""COMPUTED_VALUE"""),"012575859") -> 012575859 | K24: =IFERROR(__xludf.DUMMYFUNCTION("""COMPUTED_VALUE"""),45975.0) -> 45975 | L24: No
A25: =IFERROR(__xludf.DUMMYFUNCTION("""COMPUTED_VALUE"""),"STU-F-024") -> STU-F-024 | B25: =IFERROR(__xludf.DUMMYFUNCTION("""COMPUTED_VALUE"""),"លី សុខវឌ្ឍិកា") -> លី សុខវឌ្ឍិកា | C25: =IFERROR(__xludf.DUMMYFUNCTION("""COMPUTED_VALUE"""),"Ly Sokvadhdika") -> Ly Sokvadhdika | D25: =IFERROR(__xludf.DUMMYFUNCTION("""COMPUTED_VALUE"""),"Female") -> Female | E25: =IFERROR(__xludf.DUMMYFUNCTION("""COMPUTED_VALUE"""),"Blue") -> Blue | F25: =IFERROR(__xludf.DUMMYFUNCTION("""COMPUTED_VALUE"""),1.0) -> 1 | G25: =IFERROR(__xludf.DUMMYFUNCTION("""COMPUTED_VALUE"""),"NO") -> NO | H25: =IFERROR(__xludf.DUMMYFUNCTION("""COMPUTED_VALUE"""),40336.0) -> 40336 | I25: =IFERROR(__xludf.DUMMYFUNCTION("""COMPUTED_VALUE"""),"lysokvadhdika@gmail.com") -> lysokvadhdika@gmail.com | J25: =IFERROR(__xludf.DUMMYFUNCTION("""COMPUTED_VALUE"""),"089 996 623") -> 089 996 623 | K25: =IFERROR(__xludf.DUMMYFUNCTION("""COMPUTED_VALUE"""),45983.0) -> 45983 | L25: No
A26: =IFERROR(__xludf.DUMMYFUNCTION("""COMPUTED_VALUE"""),"STU-F-025") -> STU-F-025 | B26: =IFERROR(__xludf.DUMMYFUNCTION("""COMPUTED_VALUE"""),"ហួត ជីងហួយ") -> ហួត ជីងហួយ | C26: =IFERROR(__xludf.DUMMYFUNCTION("""COMPUTED_VALUE"""),"Hout Jinghouy") -> Hout Jinghouy | D26: =IFERROR(__xludf.DUMMYFUNCTION("""COMPUTED_VALUE"""),"Female") -> Female | E26: =IFERROR(__xludf.DUMMYFUNCTION("""COMPUTED_VALUE"""),"White") -> White | F26: =IFERROR(__xludf.DUMMYFUNCTION("""COMPUTED_VALUE"""),1.0) -> 1 | G26: =IFERROR(__xludf.DUMMYFUNCTION("""COMPUTED_VALUE"""),"NO") -> NO | H26: =IFERROR(__xludf.DUMMYFUNCTION("""COMPUTED_VALUE"""),38968.0) -> 38968 | I26: =IFERROR(__xludf.DUMMYFUNCTION("""COMPUTED_VALUE"""),"gweenja@gmail.com") -> gweenja@gmail.com | J26: =IFERROR(__xludf.DUMMYFUNCTION("""COMPUTED_VALUE"""),"085 835 924") -> 085 835 924 | K26: =IFERROR(__xludf.DUMMYFUNCTION("""COMPUTED_VALUE"""),45994.0) -> 45994 | L26: No | P26: 158 | Q26: 38
A27: =IFERROR(__xludf.DUMMYFUNCTION("""COMPUTED_VALUE"""),"STU-M-026") -> STU-M-026 | B27: =IFERROR(__xludf.DUMMYFUNCTION("""COMPUTED_VALUE"""),"ទិត ប៊ុនណាត") -> ទិត ប៊ុនណាត | C27: =IFERROR(__xludf.DUMMYFUNCTION("""COMPUTED_VALUE"""),"Tith Bunnath") -> Tith Bunnath | D27: =IFERROR(__xludf.DUMMYFUNCTION("""COMPUTED_VALUE"""),"Male") -> Male | E27: =IFERROR(__xludf.DUMMYFUNCTION("""COMPUTED_VALUE"""),"Red") -> Red | F27: =IFERROR(__xludf.DUMMYFUNCTION("""COMPUTED_VALUE"""),1.0) -> 1 | G27: =IFERROR(__xludf.DUMMYFUNCTION("""COMPUTED_VALUE"""),"NO") -> NO | H27: =IFERROR(__xludf.DUMMYFUNCTION("""COMPUTED_VALUE"""),38565.0) -> 38565 | I27: =IFERROR(__xludf.DUMMYFUNCTION("""COMPUTED_VALUE"""),"chaosbunnath@gmail.com") -> chaosbunnath@gmail.com | J27: =IFERROR(__xludf.DUMMYFUNCTION("""COMPUTED_VALUE"""),"078566058") -> 078566058 | K27: =IFERROR(__xludf.DUMMYFUNCTION("""COMPUTED_VALUE"""),46002.0) -> 46002 | L27: No
A28: =IFERROR(__xludf.DUMMYFUNCTION("""COMPUTED_VALUE"""),"STU-M-027") -> STU-M-027 | B28: =IFERROR(__xludf.DUMMYFUNCTION("""COMPUTED_VALUE"""),"មាឃ ណាហ្វេន ") -> មាឃ ណាហ្វេន | C28: =IFERROR(__xludf.DUMMYFUNCTION("""COMPUTED_VALUE"""),"Nafan Meak") -> Nafan Meak | D28: =IFERROR(__xludf.DUMMYFUNCTION("""COMPUTED_VALUE"""),"Male") -> Male | E28: =IFERROR(__xludf.DUMMYFUNCTION("""COMPUTED_VALUE"""),"White") -> White | F28: =IFERROR(__xludf.DUMMYFUNCTION("""COMPUTED_VALUE"""),1.0) -> 1 | G28: =IFERROR(__xludf.DUMMYFUNCTION("""COMPUTED_VALUE"""),"NO") -> NO | H28: =IFERROR(__xludf.DUMMYFUNCTION("""COMPUTED_VALUE"""),39754.0) -> 39754 | I28: =IFERROR(__xludf.DUMMYFUNCTION("""COMPUTED_VALUE"""),"meaknafan@gmail.com") -> meaknafan@gmail.com | J28: =IFERROR(__xludf.DUMMYFUNCTION("""COMPUTED_VALUE"""),"0969622980") -> 0969622980 | K28: =IFERROR(__xludf.DUMMYFUNCTION("""COMPUTED_VALUE"""),46004.0) -> 46004 | L28: No
A29: =IFERROR(__xludf.DUMMYFUNCTION("""COMPUTED_VALUE"""),"STU-F-028") -> STU-F-028 | B29: =IFERROR(__xludf.DUMMYFUNCTION("""COMPUTED_VALUE"""),"មុឺន កញ្ញា") -> មុឺន កញ្ញា | C29: =IFERROR(__xludf.DUMMYFUNCTION("""COMPUTED_VALUE"""),"Moeun Kanha ") -> Moeun Kanha | D29: =IFERROR(__xludf.DUMMYFUNCTION("""COMPUTED_VALUE"""),"Female") -> Female | E29: =IFERROR(__xludf.DUMMYFUNCTION("""COMPUTED_VALUE"""),"White") -> White | F29: =IFERROR(__xludf.DUMMYFUNCTION("""COMPUTED_VALUE"""),0.0) -> 0 | G29: =IFERROR(__xludf.DUMMYFUNCTION("""COMPUTED_VALUE"""),"NO") -> NO | H29: =IFERROR(__xludf.DUMMYFUNCTION("""COMPUTED_VALUE"""),39708.0) -> 39708 | I29: =IFERROR(__xludf.DUMMYFUNCTION("""COMPUTED_VALUE"""),"m.kanhaaa@gmail.com") -> m.kanhaaa@gmail.com | J29: =IFERROR(__xludf.DUMMYFUNCTION("""COMPUTED_VALUE"""),"0962320295") -> 0962320295 | K29: =IFERROR(__xludf.DUMMYFUNCTION("""COMPUTED_VALUE"""),46013.0) -> 46013 | L29: No | P29: 168 | Q29: 57
A30: =IFERROR(__xludf.DUMMYFUNCTION("""COMPUTED_VALUE"""),"STU-F-029") -> STU-F-029 | B30: =IFERROR(__xludf.DUMMYFUNCTION("""COMPUTED_VALUE"""),"ផេង ស្រីទ្រព្យ") -> ផេង ស្រីទ្រព្យ | C30: =IFERROR(__xludf.DUMMYFUNCTION("""COMPUTED_VALUE"""),"Sreytroap Pheng") -> Sreytroap Pheng | D30: =IFERROR(__xludf.DUMMYFUNCTION("""COMPUTED_VALUE"""),"Female") -> Female | E30: =IFERROR(__xludf.DUMMYFUNCTION("""COMPUTED_VALUE"""),"White") -> White | F30: =IFERROR(__xludf.DUMMYFUNCTION("""COMPUTED_VALUE"""),0.0) -> 0 | G30: =IFERROR(__xludf.DUMMYFUNCTION("""COMPUTED_VALUE"""),"NO") -> NO | H30: =IFERROR(__xludf.DUMMYFUNCTION("""COMPUTED_VALUE"""),40614.0) -> 40614 | I30: =IFERROR(__xludf.DUMMYFUNCTION("""COMPUTED_VALUE"""),"reaksmie2@gmail.com") -> reaksmie2@gmail.com | J30: =IFERROR(__xludf.DUMMYFUNCTION("""COMPUTED_VALUE"""),"78251672") -> 78251672 | K30: =IFERROR(__xludf.DUMMYFUNCTION("""COMPUTED_VALUE"""),46014.0) -> 46014 | L30: No | P30: 158 | Q30: 50
A31: =IFERROR(__xludf.DUMMYFUNCTION("""COMPUTED_VALUE"""),"STU-F-030") -> STU-F-030 | B31: =IFERROR(__xludf.DUMMYFUNCTION("""COMPUTED_VALUE"""),"ដារ៉េត កេសរបុប្ផាណា") -> ដារ៉េត កេសរបុប្ផាណា | C31: =IFERROR(__xludf.DUMMYFUNCTION("""COMPUTED_VALUE"""),"Dareth Kesorbophana ") -> Dareth Kesorbophana | D31: =IFERROR(__xludf.DUMMYFUNCTION("""COMPUTED_VALUE"""),"Female") -> Female | E31: =IFERROR(__xludf.DUMMYFUNCTION("""COMPUTED_VALUE"""),"White") -> White | F31: =IFERROR(__xludf.DUMMYFUNCTION("""COMPUTED_VALUE"""),0.0) -> 0 | G31: =IFERROR(__xludf.DUMMYFUNCTION("""COMPUTED_VALUE"""),"NO") -> NO | H31: =IFERROR(__xludf.DUMMYFUNCTION("""COMPUTED_VALUE"""),39641.0) -> 39641 | I31: =IFERROR(__xludf.DUMMYFUNCTION("""COMPUTED_VALUE"""),"bophana2474@gmail.com") -> bophana2474@gmail.com | J31: =IFERROR(__xludf.DUMMYFUNCTION("""COMPUTED_VALUE"""),"12247463") -> 12247463 | K31: =IFERROR(__xludf.DUMMYFUNCTION("""COMPUTED_VALUE"""),46017.0) -> 46017 | P31: 157 | Q31: 45
A32: =IFERROR(__xludf.DUMMYFUNCTION("""COMPUTED_VALUE"""),"STU-M-031") -> STU-M-031 | B32: =IFERROR(__xludf.DUMMYFUNCTION("""COMPUTED_VALUE"""),"សួស សុខនរៈ") -> សួស សុខនរៈ | C32: =IFERROR(__xludf.DUMMYFUNCTION("""COMPUTED_VALUE"""),"Sous Soknorak") -> Sous Soknorak | D32: =IFERROR(__xludf.DUMMYFUNCTION("""COMPUTED_VALUE"""),"Male") -> Male | E32: =IFERROR(__xludf.DUMMYFUNCTION("""COMPUTED_VALUE"""),"Yellow") -> Yellow | F32: =IFERROR(__xludf.DUMMYFUNCTION("""COMPUTED_VALUE"""),1.0) -> 1 | G32: =IFERROR(__xludf.DUMMYFUNCTION("""COMPUTED_VALUE"""),"NO") -> NO | H32: =IFERROR(__xludf.DUMMYFUNCTION("""COMPUTED_VALUE"""),42227.0) -> 42227 | I32: =IFERROR(__xludf.DUMMYFUNCTION("""COMPUTED_VALUE"""),"thearyuy@gmail.com") -> thearyuy@gmail.com | J32: =IFERROR(__xludf.DUMMYFUNCTION("""COMPUTED_VALUE"""),"89709999") -> 89709999 | K32: =IFERROR(__xludf.DUMMYFUNCTION("""COMPUTED_VALUE"""),46020.0) -> 46020
A33: =IFERROR(__xludf.DUMMYFUNCTION("""COMPUTED_VALUE"""),"STU-M-032") -> STU-M-032 | B33: =IFERROR(__xludf.DUMMYFUNCTION("""COMPUTED_VALUE"""),"សួស សុខរតនៈ") -> សួស សុខរតនៈ | C33: =IFERROR(__xludf.DUMMYFUNCTION("""COMPUTED_VALUE"""),"Sous Sokrattanak ") -> Sous Sokrattanak | D33: =IFERROR(__xludf.DUMMYFUNCTION("""COMPUTED_VALUE"""),"Male") -> Male | E33: =IFERROR(__xludf.DUMMYFUNCTION("""COMPUTED_VALUE"""),"Yellow") -> Yellow | F33: =IFERROR(__xludf.DUMMYFUNCTION("""COMPUTED_VALUE"""),1.0) -> 1 | G33: =IFERROR(__xludf.DUMMYFUNCTION("""COMPUTED_VALUE"""),"NO") -> NO | H33: =IFERROR(__xludf.DUMMYFUNCTION("""COMPUTED_VALUE"""),42760.0) -> 42760 | I33: =IFERROR(__xludf.DUMMYFUNCTION("""COMPUTED_VALUE"""),"thearyuy@gmail.com") -> thearyuy@gmail.com | J33: =IFERROR(__xludf.DUMMYFUNCTION("""COMPUTED_VALUE"""),"89709999") -> 89709999 | K33: =IFERROR(__xludf.DUMMYFUNCTION("""COMPUTED_VALUE"""),46020.0) -> 46020
A34: =IFERROR(__xludf.DUMMYFUNCTION("""COMPUTED_VALUE"""),"STU-F-033") -> STU-F-033 | B34: =IFERROR(__xludf.DUMMYFUNCTION("""COMPUTED_VALUE"""),"ឡេង សុណីតា") -> ឡេង សុណីតា | C34: =IFERROR(__xludf.DUMMYFUNCTION("""COMPUTED_VALUE"""),"Leng Soneyta") -> Leng Soneyta | D34: =IFERROR(__xludf.DUMMYFUNCTION("""COMPUTED_VALUE"""),"Female") -> Female | E34: =IFERROR(__xludf.DUMMYFUNCTION("""COMPUTED_VALUE"""),"White") -> White | F34: =IFERROR(__xludf.DUMMYFUNCTION("""COMPUTED_VALUE"""),0.0) -> 0 | G34: =IFERROR(__xludf.DUMMYFUNCTION("""COMPUTED_VALUE"""),"NO") -> NO | H34: =IFERROR(__xludf.DUMMYFUNCTION("""COMPUTED_VALUE"""),37714.0) -> 37714 | I34: =IFERROR(__xludf.DUMMYFUNCTION("""COMPUTED_VALUE"""),"soneytaleng@gmail.com") -> soneytaleng@gmail.com | J34: =IFERROR(__xludf.DUMMYFUNCTION("""COMPUTED_VALUE"""),"882077598") -> 882077598 | K34: =IFERROR(__xludf.DUMMYFUNCTION("""COMPUTED_VALUE"""),46022.0) -> 46022
A35: =IFERROR(__xludf.DUMMYFUNCTION("""COMPUTED_VALUE"""),"STU-F-034") -> STU-F-034 | B35: =IFERROR(__xludf.DUMMYFUNCTION("""COMPUTED_VALUE"""),"មាស ដា ណេ") -> មាស ដា ណេ | C35: =IFERROR(__xludf.DUMMYFUNCTION("""COMPUTED_VALUE"""),"Dane Meas") -> Dane Meas | D35: =IFERROR(__xludf.DUMMYFUNCTION("""COMPUTED_VALUE"""),"Female") -> Female | E35: =IFERROR(__xludf.DUMMYFUNCTION("""COMPUTED_VALUE"""),"White") -> White | G35: =IFERROR(__xludf.DUMMYFUNCTION("""COMPUTED_VALUE"""),"#NUM!") -> #NUM! | H35: =IFERROR(__xludf.DUMMYFUNCTION("""COMPUTED_VALUE"""),38630.0) -> 38630 | I35: =IFERROR(__xludf.DUMMYFUNCTION("""COMPUTED_VALUE"""),"msd800162@gmail.com") -> msd800162@gmail.com | J35: =IFERROR(__xludf.DUMMYFUNCTION("""COMPUTED_VALUE"""),"965880725") -> 965880725 | K35: =IFERROR(__xludf.DUMMYFUNCTION("""COMPUTED_VALUE"""),46024.0) -> 46024 | P35: 161 | Q35: 41
A36: =IFERROR(__xludf.DUMMYFUNCTION("""COMPUTED_VALUE"""),"STU-M-035") -> STU-M-035 | B36: =IFERROR(__xludf.DUMMYFUNCTION("""COMPUTED_VALUE"""),"លី ប៊ុនស័ក្ក") -> លី ប៊ុនស័ក្ក | C36: =IFERROR(__xludf.DUMMYFUNCTION("""COMPUTED_VALUE"""),"Ly Bunsak") -> Ly Bunsak | D36: =IFERROR(__xludf.DUMMYFUNCTION("""COMPUTED_VALUE"""),"Male") -> Male | E36: =IFERROR(__xludf.DUMMYFUNCTION("""COMPUTED_VALUE"""),"Red") -> Red | G36: =IFERROR(__xludf.DUMMYFUNCTION("""COMPUTED_VALUE"""),"#NUM!") -> #NUM! | H36: =IFERROR(__xludf.DUMMYFUNCTION("""COMPUTED_VALUE"""),41097.0) -> 41097 | I36: =IFERROR(__xludf.DUMMYFUNCTION("""COMPUTED_VALUE"""),"keomdaroth@gmail.com") -> keomdaroth@gmail.com | J36: =IFERROR(__xludf.DUMMYFUNCTION("""COMPUTED_VALUE"""),"85511567") -> 85511567 | K36: =IFERROR(__xludf.DUMMYFUNCTION("""COMPUTED_VALUE"""),46028.0) -> 46028 | P36: 170 | Q36: 52
A37: =IFERROR(__xludf.DUMMYFUNCTION("""COMPUTED_VALUE"""),"STU-M-036") -> STU-M-036 | B37: =IFERROR(__xludf.DUMMYFUNCTION("""COMPUTED_VALUE"""),"ប៉ែន បញ្ញាសុវណ្ណ") -> ប៉ែន បញ្ញាសុវណ្ណ | C37: =IFERROR(__xludf.DUMMYFUNCTION("""COMPUTED_VALUE"""),"Pen Panha Sovan ") -> Pen Panha Sovan | D37: =IFERROR(__xludf.DUMMYFUNCTION("""COMPUTED_VALUE"""),"Male") -> Male | E37: =IFERROR(__xludf.DUMMYFUNCTION("""COMPUTED_VALUE"""),"Brown") -> Brown | G37: =IFERROR(__xludf.DUMMYFUNCTION("""COMPUTED_VALUE"""),"#NUM!") -> #NUM! | H37: =IFERROR(__xludf.DUMMYFUNCTION("""COMPUTED_VALUE"""),40309.0) -> 40309 | I37: =IFERROR(__xludf.DUMMYFUNCTION("""COMPUTED_VALUE"""),"Sovanpanha533@gmail.com") -> Sovanpanha533@gmail.com | J37: =IFERROR(__xludf.DUMMYFUNCTION("""COMPUTED_VALUE"""),"11266571") -> 11266571 | K37: =IFERROR(__xludf.DUMMYFUNCTION("""COMPUTED_VALUE"""),46028.0) -> 46028
A38: =IFERROR(__xludf.DUMMYFUNCTION("""COMPUTED_VALUE"""),"STU-F-037") -> STU-F-037 | B38: =IFERROR(__xludf.DUMMYFUNCTION("""COMPUTED_VALUE"""),"ថាន គីមឡាង") -> ថាន គីមឡាង | C38: =IFERROR(__xludf.DUMMYFUNCTION("""COMPUTED_VALUE"""),"Than Kimlang") -> Than Kimlang | D38: =IFERROR(__xludf.DUMMYFUNCTION("""COMPUTED_VALUE"""),"Female") -> Female | E38: =IFERROR(__xludf.DUMMYFUNCTION("""COMPUTED_VALUE"""),"White") -> White | G38: =IFERROR(__xludf.DUMMYFUNCTION("""COMPUTED_VALUE"""),"#NUM!") -> #NUM! | H38: =IFERROR(__xludf.DUMMYFUNCTION("""COMPUTED_VALUE"""),38940.0) -> 38940 | I38: =IFERROR(__xludf.DUMMYFUNCTION("""COMPUTED_VALUE"""),"kimlangthan@gmail.com") -> kimlangthan@gmail.com | J38: =IFERROR(__xludf.DUMMYFUNCTION("""COMPUTED_VALUE"""),"887274203") -> 887274203 | K38: =IFERROR(__xludf.DUMMYFUNCTION("""COMPUTED_VALUE"""),46028.0) -> 46028
A39: =IFERROR(__xludf.DUMMYFUNCTION("""COMPUTED_VALUE"""),"STU-F-038") -> STU-F-038 | B39: =IFERROR(__xludf.DUMMYFUNCTION("""COMPUTED_VALUE"""),"សាន វ៉ាន់ណារី") -> សាន វ៉ាន់ណារី | C39: =IFERROR(__xludf.DUMMYFUNCTION("""COMPUTED_VALUE"""),"San Vannary") -> San Vannary | D39: =IFERROR(__xludf.DUMMYFUNCTION("""COMPUTED_VALUE"""),"Female") -> Female | E39: =IFERROR(__xludf.DUMMYFUNCTION("""COMPUTED_VALUE"""),"White") -> White | G39: =IFERROR(__xludf.DUMMYFUNCTION("""COMPUTED_VALUE"""),"#NUM!") -> #NUM! | H39: =IFERROR(__xludf.DUMMYFUNCTION("""COMPUTED_VALUE"""),46038.0) -> 46038 | I39: =IFERROR(__xludf.DUMMYFUNCTION("""COMPUTED_VALUE"""),"sanvannary11@gmail.com") -> sanvannary11@gmail.com | J39: =IFERROR(__xludf.DUMMYFUNCTION("""COMPUTED_VALUE"""),"884703618") -> 884703618 | K39: =IFERROR(__xludf.DUMMYFUNCTION("""COMPUTED_VALUE"""),46028.0) -> 46028 | P39: 169 | Q39: 62
A40: =IFERROR(__xludf.DUMMYFUNCTION("""COMPUTED_VALUE"""),"STU-M-039") -> STU-M-039 | B40: =IFERROR(__xludf.DUMMYFUNCTION("""COMPUTED_VALUE"""),"ឆាយ ឃុនម៉េង") -> ឆាយ ឃុនម៉េង | C40: =IFERROR(__xludf.DUMMYFUNCTION("""COMPUTED_VALUE"""),"Khunmeng Chhay") -> Khunmeng Chhay | D40: =IFERROR(__xludf.DUMMYFUNCTION("""COMPUTED_VALUE"""),"Male") -> Male | E40: =IFERROR(__xludf.DUMMYFUNCTION("""COMPUTED_VALUE"""),"Red") -> Red | G40: =IFERROR(__xludf.DUMMYFUNCTION("""COMPUTED_VALUE"""),"#NUM!") -> #NUM! | H40: =IFERROR(__xludf.DUMMYFUNCTION("""COMPUTED_VALUE"""),40848.0) -> 40848 | I40: =IFERROR(__xludf.DUMMYFUNCTION("""COMPUTED_VALUE"""),"khunmeng570818@gmail.com") -> khunmeng570818@gmail.com | J40: =IFERROR(__xludf.DUMMYFUNCTION("""COMPUTED_VALUE"""),"12570818") -> 12570818 | K40: =IFERROR(__xludf.DUMMYFUNCTION("""COMPUTED_VALUE"""),46029.0) -> 46029
...

Sheet Achievements
A1: Student ID | B1: Student Name | C1: Event Name | D1: Date | E1: Category | F1: Division | G1: Medal/Rank | H1: Notes | I1: Description
A2: {=IF(B2:B67="", "", IFERROR(XLOOKUP(B2:B67, Students!C:C, Students!A:A), "Not Found"))} -> STU-F-001 | B2: Saopich Rithyna | C2: Korean Ambassador's Cup Taekwondo Competition 2025 | D2: 45912 | E2: Demonstration | F2: Team | G2: Gold
A3: STU-M-002 | B3: Hak Lymeng | C3: Korean Ambassador's Cup Taekwondo Competition 2025 | D3: 45912 | E3: Demonstration | F3: Team | G3: Gold
A4: STU-F-003 | B4: Oeng Chamroeunreasey | C4: Korean Ambassador's Cup Taekwondo Competition 2025 | D4: 45912 | E4: Demonstration | F4: Team | G4: Gold
A5: STU-F-001 | B5: Saopich Rithyna | C5: Kampong Chhnang Provincial Taekwondo Championship 2025 | D5: 45990 | E5: Recognized Poomsae | F5: Female Individual | G5: Silver
A6: STU-F-006 | B6: Neou Thidapin | C6: Kampong Chhnang Provincial Taekwondo Championship 2025 | D6: 45990 | E6: Recognized Poomsae | F6: Female Individual | G6: Bronze
A7: STU-F-007 | B7: Aboubakar Rosnavattey | C7: Kampong Chhnang Provincial Taekwondo Championship 2025 | D7: 45990 | E7: Recognized Poomsae | F7: Female Individual | G7: Gold
A8: STU-F-003 | B8: Oeng Chamroeunreasey | C8: Waein cup open championship 2025, Singapore | D8: 46008 | E8: Recognized Poomsae | F8: Female Individual | G8: Bronze
A9: STU-F-003 | B9: Oeng Chamroeunreasey | C9: Waein cup open championship 2025, Singapore | D9: 46008 | E9: Recognized Poomsae | F9: Team | G9: Silver
A10: STU-F-007 | B10: Aboubakar Rosnavattey | C10: Cambodia Taekwondo Hope Competition 2023 | D10: 45270 | E10: Recognized Poomsae | F10: Female Individual | G10: Silver
A11: STU-F-007 | B11: Aboubakar Rosnavattey | C11: Best of the Best 2023 | D11: 45290 | E11: Recognized Poomsae | F11: Female Individual | G11: Bronze
A12: STU-F-007 | B12: Aboubakar Rosnavattey | C12: Cambodia Taekwondo Hope Competition 2024 - season 1 | D12: 45416 | E12: Recognized Poomsae | F12: Female Individual | G12: Gold
A13: STU-F-007 | B13: Aboubakar Rosnavattey | C13: Cambodia Taekwondo Hope Competition 2024 - season 2 | D13: 45528 | E13: Recognized Poomsae | F13: Female Individual | G13: Gold
A14: STU-F-007 | B14: Aboubakar Rosnavattey | C14: Cambodia Taekwondo National Championship 2024 | D14: 45646 | E14: Recognized Poomsae | F14: Female Individual | G14: Bronze
... A36: STU-F-017 | B36: Pen Sothea | C36: 1st Hope International Taekwondo Open Championship 2026 | D36: 46031 | E36: Recognized Poomsae | F36: Female Individual | G36: Gold

Sheet Belt History
A1: Student ID | B1: Belt | C1: Promotion Date | D1: Result | E1: Student Name
A2: {=IF(E2:E95="", "", IFERROR(XLOOKUP(E2:E95, Students!C:C, Students!A:A), "Not Found"))} -> STU-F-001 | B2: Brown | C2: 45776 | E2: Saopich Rithyna
A3: STU-F-001 | B3: Red | C3: 45897 | E3: Saopich Rithyna
A4: STU-F-001 | B4: 1st Poom/Dan | C4: 45958 | E4: Saopich Rithyna
A5: STU-F-012 | B5: Yellow | C5: 45352 | E5: Ty Vorleak
A6: STU-F-012 | B6: Green | C6: 45383 | E6: Ty Vorleak
A7: STU-F-012 | B7: Blue | C7: 45505 | E7: Ty Vorleak
A8: STU-F-012 | B8: Brown | C8: 45597 | E8: Ty Vorleak
A9: STU-F-012 | B9: Red | C9: 45658 | E9: Ty Vorleak
A10: STU-F-012 | B10: 1st Poom/Dan | C10: 45775 | E10: Ty Vorleak
A11: STU-F-006 | B11: Yellow | C11: 43421 | E11: Neou Thidapin
A12: STU-F-006 | B12: Green | C12: 43495 | E12: Neou Thidapin
A13: STU-F-006 | B13: Blue | C13: 43561 | E13: Neou Thidapin
A14: STU-F-006 | B14: Brown | C14: 43653 | E14: Neou Thidapin
... A66: STU-M-040 | B66: Yellow | C66: 46039 | E66: Daleap Phalla

Sheet Events
A1: Name | B1: Type | C1: Reg Start | D1: Reg Close | E1: Event Start | F1: Event Close | G1: Location | H1: Description | I1: Status
A2: Cambodia Taekwondo Hope Competition 2023 | B2: Competition | E2: 10-Dec-2023 | F2: 10-Dec-2023 | G2: Phnom Penh, Cambodia | I2: Closed
A3: Cambodia Taekwondo Hope Competition 2024 - season 1 | B3: Competition | E3: 4-May-2024 | F3: 4-May-2024 | G3: Phnom Penh, Cambodia | I3: Closed
A4: Cambodia Taekwondo Hope Competition 2024 - season 2 | B4: Competition | E4: 24-Aug-2024 | F4: 24-Aug-2024 | G4: Phnom Penh, Cambodia | I4: Closed
A5: Cambodia Taekwondo Hope Competition 2025 | B5: Competition | E5: 15-Mar-2025 | F5: 15-Mar-2025 | G5: Phnom Penh, Cambodia | I5: Closed
A6: Best of the Best 2023 | B6: Competition | E6: 30-Dec-2023 | F6: 30-Dec-2024 | G6: Phnom Penh, Cambodia | I6: Closed
A7: Waein cup open championship 2025, Singapore | B7: Competition | E7: 17-Dec-2025 | F7: 17-Dec-2025 | G7: Singapore | I7: Closed
A8: 7th Heros International Taekwondo Cup 2025, Malaysia | B8: Competition | E8: 9-Aug-2025 | F8: 9-Aug-2025 | G8: Negeri Smbilan, Malaysia | I8: Closed
A9: Cambodia Taekwondo National Championship 2024 | B9: Competition | E9: 20-Dec-2024 | F9: 20-Dec-2025 | G9: Phnom Penh, Cambodia | I9: Closed
A10: National School Game (NSG) 2024, Singapore | B10: Competition | E10: 13-May-2024 | F10: 13-May-2024 | G10: Singapore | I10: Closed
A11: NTU's Tournament of Champions (TOC), Singapore | B11: Competition | E11: 8-Mar-2025 | F11: 8-Mar-2025 | G11: Singapore | I11: Closed
A12: National School Game (NSG) 2025, Singapore | B12: Competition | E12: 13-May-2025 | F12: 13-May-2025 | G12: Singapore | I12: Closed
A13: Korean Ambassador's Cup Taekwondo Competition 2025 | B13: Competition | C13: 1-Aug-2025 | D13: 20-Aug-2025 | E13: 12-Sep-2025 | F13: 12-Sep-2026 | G13: Phnom Penh, Cambodia | I13: Closed
A14: Kampong Chhnang Provincial Taekwondo Championship 2025 | B14: Competition | C14: 1-Nov-2025 | D14: 20-Nov-2025 | E14: 28-Nov-2025 | F14: 29-Nov-2025 | G14: Kampong Chhnang, Cambodia | I14: Closed
A15: 1st Hope International Taekwondo Open Championship 2026 | B15: Competition | C15: 1-Oct-2025 | D15: 9-Dec-2025 | E15: 8-Jan-2026 | F15: 11-Jan-2026 | G15: Phnom Penh, Cambodia | I15: Closed
A16: Cambodia Taekwondo National Championship 2025 | B16: Competition | G16: Phnom Penh, Cambodia | H16: For Black Belt only | I16: Open

Sheet Attendance
A1: Student ID | B1: Student Name | C1: Date | D1: Status
A2: {=IF(B2:B660="", "", IFERROR(XLOOKUP(B2:B660, Students!C:C, Students!A:A), "Not Found"))} -> STU-F-001 | B2: Saopich Rithyna | C2: 45927 | D2: Absent
A3: STU-F-001 | B3: Saopich Rithyna | C3: 45928 | D3: Absent
A4: STU-F-001 | B4: Saopich Rithyna | C4: 45934 | D4: Absent
A5: STU-F-001 | B5: Saopich Rithyna | C5: 45935 | D5: Present
A6: STU-F-001 | B6: Saopich Rithyna | C6: 45942 | D6: Absent
A7: STU-F-001 | B7: Saopich Rithyna | C7: 45948 | D7: Present
A8: STU-F-001 | B8: Saopich Rithyna | C8: 45949 | D8: Present
A9: STU-F-001 | B9: Saopich Rithyna | C9: 45955 | D9: Present
A10: STU-F-001 | B10: Saopich Rithyna | C10: 45956 | D10: Present
A11: STU-F-001 | B11: Saopich Rithyna | C11: 45962 | D11: Present
A12: STU-F-001 | B12: Saopich Rithyna | C12: 45963 | D12: Late
A13: STU-F-001 | B13: Saopich Rithyna | C13: 45969 | D13: Present
A14: STU-F-001 | B14: Saopich Rithyna | C14: 45970 | D14: Present
... A311: STU-M-027 | B311: Nafan Meak | C311: 46011 | D311: Absent

Sheet Payment_Tracker
A1: Year | D1: 2026
A3: Student ID | B3: Khmer Full Name | C3: English Full Name | D3: Jan | E3: Feb | F3: Mar | G3: Apr | H3: May | I3: Jun | J3: Jul | K3: Aug | L3: Sep | M3: Oct | N3: Nov | O3: Dec
A4: {=IF(COUNTA(Students!A2:A50)=0, "No Students Found", IFERROR(Students!A2:C50, ""))} -> STU-F-001 | B4: សៅពេជ្រ រិទ្ធីណា | C4: Saopich Rithyna
A5: STU-M-002 | B5: ហាក់ លីម៉េង | C5: Hak Lymeng
A6: STU-F-003 | B6: អុឹង ចំរើនរាសី | C6: Oeng Chamroeunreasey | D6: Paid
A7: STU-F-004 | B7: មិត សុធា | C7: Sothea Mith
A8: STU-F-005 | B8: ហែម កែវទិត្យសុបុណ្យនារី | C8: Hem Keotetsobonneary
A9: STU-F-006 | B9: នៅ ធីតាពីន | C9: Neou Thidapin
A10: STU-F-007 | B10: អាពូបាកា រ៉ូសនាវ៉ាត្តី | C10: Aboubakar Rosnavattey
A11: STU-F-008 | B11: នុត ដានីតា | C11: Nuth Danita
A12: STU-M-009 | B12: ភេន ឌីណា | C12: Dina Pan
A13: STU-M-010 | B13: សោម សុវិន | C13: Soam Sovin
A14: STU-F-011 | B14: ឃានកែវ បាបឺរ៉ា | C14: Kheankeo Babera
A15: STU-F-012 | B15: ទី វរលក្ខណ៍ | C15: Ty Vorleak
A16: STU-F-013 | B16: សំនៀង ឡេអុងទីន | C16: Samneang Leongtin | D16: Paid
A17: STU-F-014 | B17: ធួក សុធានីន | C17: Thuok Sotheanin
A18: STU-F-015 | B18: វ៉ាន់ដូរ ជេនិសា | C18: Vando Chenisa
A19: STU-F-016 | B19: វ៉ាន់ដូរ ជេនិតា | C19: Vando Chenita
A20: STU-F-017 | B20: ប៉ែន សុធា | C20: Pen Sothea
A21: STU-F-018 | B21: នន់ សីហា | C21: Nun Seyha
A22: STU-F-019 | B22: ចៅ បូរ៉ែនណា | C22: Chau Boreinna
A23: STU-M-020 | B23: សុភា រតនៈ | C23: Sophea Ratanak
A24: STU-M-021 | B24: យ៉ែម សភា | C24: Yem Sakphea
A25: STU-M-022 | B25: ឈៀង ហុងហេង | C25: Chheang Hongheng
A26: STU-F-023 | B26: ផាន់ អារ៉ាន់យ៉ា | C26: Phan Aranya
A27: STU-F-024 | B27: លី សុខវឌ្ឍិកា | C27: Ly Sokvadhdika | D27: Paid
A28: STU-F-025 | B28: ហួត ជីងហួយ | C28: Hout Jinghouy | D28: Paid
A29: STU-M-026 | B29: ទិត ប៊ុនណាត | C29: Tith Bunnath
A30: STU-M-027 | B30: មាឃ ណាហ្វេន | C30: Nafan Meak
A31: STU-F-028 | B31: មុឺន កញ្ញា | C31: Moeun Kanha | D31: Paid
A32: STU-F-029 | B32: ផេង ស្រីទ្រព្យ | C32: Sreytroap Pheng | D32: Paid
A33: STU-F-030 | B33: ដារ៉េត កេសរបុប្ផាណា | C33: Dareth Kesorbophana | D33: Paid
A34: STU-M-031 | B34: សួស សុខនរៈ | C34: Sous Soknorak
A35: STU-M-032 | B35: សួស សុខរតនៈ | C35: Sous Sokrattanak
A36: STU-F-033 | B36: ឡេង សុណីតា | C36: Leng Soneyta | D36: Paid
A37: STU-F-034 | B37: មាស ដា ណេ | C37: Dane Meas | D37: Paid
A38: STU-M-035 | B38: លី ប៊ុនស័ក្ក | C38: Ly Bunsak
A39: STU-M-036 | B39: ប៉ែន បញ្ញាសុវណ្ណ | C39: Pen Panha Sovan
A40: STU-F-037 | B40: ថាន គីមឡាង | C40: Than Kimlang
A41: STU-F-038 | B41: សាន វ៉ាន់ណារី | C41: San Vannary
...

Sheet Belt_Curriculum
A1: Belt_Level | B1: Category | C1: Title | D1: Sub_Title | E1: Description | F1: Focus | G1: Video_URL | H1: Tag | I1: Level | J1: Prerequisite
A2: White | B2: Poomsae | C2: Poomsae 1 | D2: Taeguek II Jang | E2: This poomsae symbolizes the Heaven and the Light. It focuses on the basic moves for beginners, helping students to understand how to control their stances, strikes, and blocks. | F2: Beginnings of balance, fundamental stances, and basic hand and foot techniques. | G2: https://www.youtube.com/watch?v=WhkjRruCBTo | H2: Recognized Poomsae | I2: Fundamental | J2: Front Kick
A3: Yellow | B3: Poomsae | C3: Poomsae 2 | D3: Taeguek Ee Jang | E3: This poomsae represents Joy and the Thunder. It teaches students to refine their footwork and adds more complexity to their movements. The patterns emphasize turning and the use of blocks and strikes with precision. | F3: Developing further control over stances and basic techniques. | G3: https://www.youtube.com/watch?v=tGlrUplKHh8 | H3: Recognized Poomsae | I3: Fundamental | J3: Poomsae 1
A4: Yellow | B4: Poomsae | C4: Poomsae 3 | D4: Taeguek Sam Jang | E4: Symbolizes Fire and the Sun, representing energy and power. The movements become more complex, with an emphasis on proper breathing and rhythm. | F4: Stronger focus on control, balance, and synchronization between hand and foot techniques. | G4: https://www.youtube.com/watch?v=ksSqKt0UkWo | H4: Recognized Poomsae | I4: Fundamental | J4: Poomsae 2
A5: Green | B5: Poomsae | C5: Poomsae 4 | D5: Taeguek Sa Jang | E5: This poomsae represents Thunder and the Earth, with an emphasis on solid, powerful movements. Techniques include high blocks and low stances, which challenge students to maintain strength in their forms. | F5: Strengthening of the stances, with more focus on speed and accuracy. | G5: https://www.youtube.com/watch?v=Lt917gacJho | H5: Recognized Poomsae | I5: Intermediate | J5: Poomsae 3, Side Kick
A6: Blue | B6: Poomsae | C6: Poomsae 5 | D6: Taeguek O Jang | E6: Symbolizing Wind and the Mountain, this form introduces more dynamic movement and speed, including techniques that require quicker reactions. | F6: Coordination between blocking and striking, while maintaining balanced and powerful stances. | G6: https://www.youtube.com/watch?v=VdqNEAHWCBM | H6: Recognized Poomsae | I6: Intermediate | J6: Poomsae 4, Side Kick
A7: Blue | B7: Poomsae | C7: Poomsae 6 | D7: Taeguek Yuk Jang | E7: Representing Water and the Lake, this form emphasizes how to move with grace and agility, with techniques requiring fluid transitions between blocks and strikes. | F7: Fluid transitions between stances and a focus on speed and precision. | G7: https://www.youtube.com/watch?v=jcBwWo4wN7c | H7: Recognized Poomsae | I7: Intermediate | J7: Poomsae 5, Roundhouse Kick, Front Kick
A8: Brown | B8: Poomsae | C8: Poomsae 7 | D8: Taeguek Chil Jang | E8: Symbolizing Heaven and the Earth, this poomsae builds on the previous forms and emphasizes solid, strong movements with the introduction of more advanced techniques. | F8: Power and confidence in performing the forms. | G8: https://www.youtube.com/watch?v=6FUM1p6qqhQ | H8: Recognized Poomsae | I8: Advanced | J8: Poomsae 6, Front Kick
A9: Brown | B9: Poomsae | C9: Poomsae 8 | D9: Taeguek Pal Jang | E9: Representing Infinity and Completion, this poomsae ties all previous forms together. It requires the practitioner to demonstrate mastery over stances, footwork, and technique, showcasing balance and power. | F9: The pinnacle of the Taegeuk series, requiring strength, control, and fluidity. | G9: https://www.youtube.com/watch?v=Gr_Je2ZkgkI | H9: Recognized Poomsae | I9: Advanced | J9: Poomsae 7
A10: Red | B10: Poomsae | C10: Koryo | D10: 고려 | E10: Koryo symbolizes the wisdom and virtue of a scholar. This form combines precise, quick movements with powerful blocks and strikes. It challenges students to demonstrate their ability to control their body and use focus and energy efficiently in each movement. | F10: Combination of speed, power, and control. | G10: https://www.youtube.com/watch?v=mGa60JDtWmg | H10: Recognized Poomsae | I10: Advanced | J10: Poomsae 8, Jumping Front Kick
A11: Red | B11: Poomsae | C11: Keumgang | D11: 금강 | E11: Named after the Keumgang Mountain in Korea, which symbolizes hardness and strength. This poomsae focuses on creating powerful, direct movements and balancing speed with control. There is a focus on the integrity of each stance and movement. | F11: Precision, balance, and creating power in each strike. | G11: https://www.youtube.com/watch?v=CRGVSOmaQaY | H11: Recognized Poomsae | I11: Senior
A12: Red | B12: Poomsae | C12: Taebaek | D12: 태백 | E12: Taebaek refers to the legendary Taebaek Mountain in Korea. It represents the starting point of everything, symbolizing a new beginning. This form includes a series of advancing and retreating moves, requiring fluid transitions between blocks, strikes, and stances. Precision is key. | F12: The power and grace of movement, with an emphasis on circular motion and technique. | G12: https://www.youtube.com/watch?v=Q4dYdFRbE4U | H12: Recognized Poomsae | I12: Senior
A13: Black 1 Poom/Dan | B13: Poomsae | C13: Pyongwon | D13: 평원 | E13: Pyongwon symbolizes the wide and vast land. It includes expansive techniques and movements, requiring more agility and speed. The form uses a range of stances, and students need to maintain balance, breath control, and power throughout. | F13: Concentration, speed, and agility, with more complex patterns. | G13: https://www.youtube.com/watch?v=RB-7mBtvtZw | H13: Recognized Poomsae | I13: Senior
A14: Black 1 Poom/Dan | B14: Poomsae | C14: Sipjin | D14: 십진 | E14: This form represents long-lasting wisdom, symbolizing the calm but powerful nature of a mountain. Sipjin focuses on intricate footwork and hand movements. It requires a high level of discipline and control. | F14: Precision in technique and fluidity in movement. | G14: https://www.youtube.com/watch?v=hOZB0IESJ38 | H14: Recognized Poomsae | I14: Senior
A15: Black 1 Poom/Dan | B15: Poomsae | C15: Jitae | D15: 지태 | E15: Jitae represents the earth and its core. This form requires fluid, circular movements and focuses on balanced stances and blocks. It is more spiritual in nature, as it asks the practitioner to align their mind, body, and spirit. | F15: The integration of technique and spirituality. | G15: https://www.youtube.com/watch?v=nur2WsN7dQw | H15: Recognized Poomsae | I15: Senior
A16: Black 1 Poom/Dan | B16: Poomsae | C16: Himchari | D16: 힘차리 | E16: Himchari is an advanced poomsae that emphasizes strength and stability. The name "Himchari" translates roughly to "powerful" or "to strike strongly," reflecting the emphasis on delivering controlled, powerful movements with intention. | F16: Emphasizes powerful strikes, stability, and energy control in each movement. | G16: https://www.youtube.com/watch?v=FcCts3yYaW8 | H16: New Poomsae | I16: Elite
A17: Black 2 Poom/Dan | B17: Poomsae | C17: Yamang | D17: 야망 | E17: Yamang is designed to help students refine their control over both their physical movements and mental focus. The term "Yamang" translates to "ambition" or "aspiration," encouraging practitioners to embody perseverance and strength in their training. | F17: Teaches control, precision, and the mental strength of perseverance and ambition. | G17: https://www.youtube.com/watch?v=lFG994zIt0Q | H17: New Poomsae | I17: Elite
A18: Black 2 Poom/Dan | B18: Poomsae | C18: Saebyeol | D18: 새별 | E18: "Saebyeol" translates to "new star" or "rising star," symbolizing a new beginning or fresh growth. This poomsae is often taught as a way to symbolize personal evolution and awakening. | F18: Focuses on fluid transitions, flexibility, and energy timing, symbolizing personal growth. | G18: https://www.youtube.com/watch?v=uNF9KFiOlnE | H18: New Poomsae | I18: Elite
A19: Black 2 Poom/Dan | B19: Poomsae | C19: Nareusya | D19: 나르세요 | E19: The name "Nareusya" translates to "downward" or "falling." This poomsae emphasizes downward strikes and controlling downward motion, often symbolizing humility, grounding, and the ability to control one's own strength. | F19: Strengthens downward techniques and stances, promoting grounding and control. | G19: https://www.youtube.com/watch?v=mglxY9DK8Gs | H19: New Poomsae | I19: Elite
A20: Black 2 Poom/Dan | B20: Poomsae | C20: Bigak | D20: 비각 | E20: "Bigak" is typically associated with strategic awareness and angles of attack. The name can be interpreted as "mystic angle" or "unseen attack," symbolizing the importance of being unpredictable and calculated in one’s movements. | F20: Focuses on strategic angles, speed, and defensive reflexes in combat. | G20: https://www.youtube.com/watch?v=s0GSoI8UM4U | H20: New Poomsae | I20: Elite
A21: White | B21: Kick | C21: Front Kick | D21: Ap Chagi | E21: The front kick is a straightforward and powerful strike, typically aimed at an opponent’s midsection or head. It is executed by lifting the knee, extending the foot forward, and striking with the ball of the foot. The kick should be quick and precise, using the hip for added power. | F21: Speed, precision, and control using the ball of the foot. | H21: Normal Kick | I21: Fundamental
A22: White | B22: Kick | C22: Axe Kick | D22: Naeryo Chagi | E22: The axe kick is performed by raising the leg straight up, then bringing it down sharply in a downward motion, like an axe chopping wood. It is delivered with the heel, and the downward trajectory makes it useful for striking an opponent's head or shoulders. | F22: Height and downward impact, striking with the heel. | H22: Normal Kick | I22: Fundamental
A23: White | B23: Kick | C23: Roundhouse Kick | D23: Dollyo Chagi | E23: A roundhouse kick involves pivoting on the supporting foot while bringing the kicking leg in a circular motion to strike the target with the instep or shin. It can be aimed at various heights, from the midsection to the head. The roundhouse kick is one of the most versatile kicks. | F23: Power and rotation, striking with the instep or shin. | H23: Normal Kick | I23: Fundamental
A24: Yellow | B24: Kick | C24: Crescent Kick | D24: Bandal Chagi | E24: The crescent kick is an arc-shaped kick that starts low and swings upward in a semicircular motion, striking with the inside or outside of the foot. It’s executed by raising the leg to the side and sweeping it in a crescent motion. | F24: Fluid arc motion, striking with the inside or outside of the foot. | H24: Normal Kick | I24: Fundamental
A25: Yellow | B25: Kick | C25: Push Kick | D25: Meereo Chagi | E25: The push kick is delivered by thrusting the ball of the foot directly at the opponent, usually targeting their chest or abdomen. The kick is quick and explosive, intended more to push the opponent away than to cause significant damage. | F25: Distance control, using the ball of the foot to push away. | H25: Normal Kick | I25: Fundamental
A26: Yellow | B26: Kick | C26: Jumping Front Kick | D26: Ttwieo Ap Chagi | E26: The jumping front kick is performed by lifting the knee, jumping upward, and extending the kicking leg forward while airborne. The kick strikes with the ball of the foot and emphasizes timing, balance, and explosive power. | F26: Timing and elevation, adding power with height. | H26: Special Kick | I26: Intermediate | J26: Front Kick
A27: Yellow | B27: Kick | C27: Jumping Round Kick | D27: Ttwieo Dollyo Chagi | E27: This kick combines a jump with a roundhouse motion, striking the target while airborne using the instep. The hips rotate mid-air to generate power and reach higher targets. | F27: Airborne rotation and precision while kicking. | H27: Special Kick | I27: Intermediate | J27: Roundhouse Kick
A28: Yellow | B28: Kick | C28: 360 Round Kick | D28: Tornado Kick | E28: A spinning kick where the practitioner turns the body a full 360 degrees before executing a roundhouse kick. It combines rotational momentum, balance, and precise timing to deliver a powerful and dynamic strike. | F28: Full spin and precision, focusing on balance and control. | H28: Special Kick | I28: Intermediate | J28: Jumping Round Kick
A29: Green | B29: Kick | C29: Hook Kick | D29: Huryeo Chagi | E29: The hook kick is similar to the roundhouse kick, but with a more circular, hooking motion. The kick is delivered with the heel and is aimed at the opponent’s head, neck, or ribs. The foot follows a path like a hook, coming around the target from behind. | F29: Speed, flexibility, and retraction | H29: Normal Kick | I29: Fundamental
A30: Green | B30: Kick | C30: Downward Kick | D30: Naeryo Chagi | E30: The downward kick is similar to the axe kick but more focused on a sharp downward angle. The kick is executed by raising the leg high and then driving it down onto the target, typically using the heel. | F30: Precision and downward force, targeting low points. | H30: Normal Kick | I30: Intermediate
